<?xml version="1.0" encoding="UTF-8"?>
<robot xmlns:xacro="http://www.ros.org/wiki/xacro" name="kamayuc">

    <!--Include macros for materials, sensors-->
    <xacro:include filename="$(find kamayuc_description)/urdf/rover_materials.xacro"/>

    <!-- Constants-->
    <xacro:property name="math_pi"        value="3.141592653589793" />
    <xacro:property name="math_pi_over_2" value="1.5707963267948966" />
    <xacro:property name="math_pi_over_4" value="0.785398163397448" />
    <xacro:property name="math_pi_over_6" value="0.523598776" />
    <xacro:property name="math_pi_over_8" value="0.392699082" />
    <xacro:property name="math_pi_over_16" value="0.196349541" />

    <!-- Model-->
    <gazebo>
        <plugin name="gazebo_ros_control" filename="libgazebo_ros_control.so">
            <robotNamespace>/</robotNamespace>
        </plugin>
    </gazebo>
    
    <link name="base_link">
        <visual>
            <origin rpy="0 0 0" xyz="0 0 0"/>
            <geometry>
                <cylinder radius="0.02" length="0.02"/>
            </geometry>
        </visual>
    </link>

    <!--Body-->
    <link name="chasis">
        <inertial>
            <origin xyz="0 0 0" rpy="0 0 0"/>
            <mass value="0.25"/>
            <inertia ixx="0.011042" ixy="0" ixz="0" iyy="0.01046" iyz="0" izz="0.01984"/>
        </inertial>
        <collision>
            <origin xyz="0 0 0" rpy="0 0 0"/>
            <geometry>
                <box size="0.68 0.7 0.2"/>
            </geometry>
        </collision>
        <visual>
            <origin rpy="0 0 0" xyz="0 0 0"/>
            <geometry>
                <!--box size="0.68 0.7 0.2"/-->
                <mesh filename="package://kamayuc_description/meshes/base/rover_chasis.dae"/>
            </geometry>
        </visual>
    </link>

    <gazebo reference="chasis">
        <material>Gazebo/Grey</material>
    </gazebo>

    <joint name="chasis_base_joint" type="fixed">
        <origin xyz="0 0 0" rpy="0 0 0"/>
        <parent link="base_link"/>
        <child link="chasis"/>
    </joint>

    <!--RIGHT OF ROVER-->

    <!--First coupling-->
    <link name="right_free_up">
        <inertial>
            <origin xyz="0 0 0" rpy="1.5708 0 0"/>
            <mass value="0.05"/>
            <inertia ixx="6.67e-06" ixy="0" ixz="0" iyy="6.67e-06" iyz="0" izz="1e-05"/>
        </inertial>
        <visual>
            <origin xyz="0 0 0" rpy="1.5708 0 0"/>
            <geometry>
                <!--cylinder radius="0.02" length="0.02"/-->
                <mesh filename="package://kamayuc_description/meshes/legs/rover_r_first_acople.dae"/>
            </geometry>
        </visual>
    </link>

    <gazebo reference="right_free_up">
        <material>Gazebo/Grey</material>
    </gazebo>

    <joint name="right_up_chasis_joint" type="revolute">
        <origin xyz="0 -0.36 0"/>
        <!--limit lower="${-math_pi_over_4}" upper="${math_pi_over_4}" effort="100.0" velocity="100.0"/-->
        <axis xyz="0 1 0"/>
        <limit 
            lower="${-math_pi_over_16}"
            upper="${math_pi_over_16}"
            effort="100.0"
            velocity="100.0" />
        <parent link="chasis"/>
        <child link="right_free_up"/>
    </joint>

    <gazebo reference="right_up_chasis_joint">
        <provideFeedback>true</provideFeedback>
        <implicitSpringDamper>true</implicitSpringDamper>
        <!-- <springStiffness>0.0</springStiffness> -->
        <!-- <springReference>0.0</springReference> -->
    </gazebo>

    <!--Right l1-->
    <link name="right_l1">
        <inertial>
            <origin xyz="0 0 0" rpy="0 0.8456 0"/>
            <mass value="0.1"/>
            <inertia ixx="0.003394" ixy="0" ixz="0" iyy="0.003394" iyz="0" izz="1.445e-05"/>
        </inertial>
        <collision>
            <origin xyz="0 0 0" rpy="0 0.8456 0"/>
            <geometry>
                <cylinder radius="0.017" length="0.6375"/>
            </geometry>
        </collision>
        <visual>
            <origin xyz="0 0 0" rpy="0 0.8456 0"/>
            <geometry>
                <!--cylinder radius="0.017" length="0.6375"/-->
                <mesh filename="package://kamayuc_description/meshes/legs/rover_r_leg1.dae"/>
            </geometry>
        </visual>
    </link>

    <gazebo reference="right_l1">
        <material>Gazebo/Grey</material>
    </gazebo>

    <joint name="right_up_l1_joint" type="fixed">
        <origin xyz="-0.253511 0 -0.224685" rpy="0 0 0"/>
        <parent link="right_free_up"/>
        <child link="right_l1"/>
    </joint>
    
    <!--Wheel l1-->
    <link name="right_w_l1_link">
        <inertial>
            <origin xyz="0 0 0" rpy="1.5708 0 0"/>
            <mass value="0.2"/>
            <inertia ixx="0.001145" ixy="0" ixz="0" iyy="0.001145" iyz="0" izz="0.00121"/>
        </inertial>
        <collision>
            <origin xyz="0 0 0" rpy="1.5708 0 0"/>
            <geometry>
                <cylinder length="0.18" radius="0.11"/>
            </geometry>
        </collision>
        <visual>
            <origin xyz="0 0 0" rpy="0 0 0"/>
            <geometry>
                <!--cylinder length="0.18" radius="0.11"/-->
                <mesh filename="package://kamayuc_description/meshes/wheels/rover_r_wheel.dae"/>
            </geometry>
        </visual>
    </link>

    <gazebo reference="right_w_l1_link">
        <material>Gazebo/DarkGrey</material>
    </gazebo>

    <joint name="right_w_l1_joint" type="continuous">
        <axis xyz="0 1 0"/>
        <origin xyz="-0.253511 -0.107 -0.224685"/>
        <parent link="right_l1"/>
        <child link="right_w_l1_link"/>
    </joint>

    <transmission name="right_w_l1_transmission">
        <type>transmission_interface/SimpleTransmission</type>
        <actuator name="right_w_l1_actuator">
            <mechanicalReduction>1</mechanicalReduction>
        </actuator>
        <joint name="right_w_l1_joint">
            <hardwareInterface>hardware_interface/VelocityJointInterface</hardwareInterface>
        </joint>
    </transmission>

    <gazebo reference="right_w_l1_joint">
        <provideFeedback>true</provideFeedback>
    </gazebo>


    <!--Right l2-->
    <link name="right_l2">
        <inertial>
            <origin xyz="0 0 0" rpy="0 -0.89972 0"/>
            <mass value="0.1"/>
            <inertia ixx="0.001087225" ixy="0" ixz="0" iyy="0.001087225" iyz="0" izz="1.445e-05"/>
        </inertial>
        <collision>
            <origin xyz="0 0 0" rpy="0 -0.89972 0"/>
            <geometry>
                <cylinder radius="0.017" length="0.36"/>
            </geometry>
        </collision>
        <visual>
            <origin xyz="0 0 0" rpy="0 -0.89972 0"/>
            <geometry>
                <!--cylinder radius="0.017" length="0.36"/-->
                <mesh filename="package://kamayuc_description/meshes/legs/rover_r_leg2.dae"/>
            </geometry>
        </visual>
    </link>

    <gazebo reference="right_l2">
        <material>Gazebo/Grey</material>
    </gazebo>

    <joint name="right_up_l2_joint" type="fixed">
        <origin xyz="0.156631 0 -0.124365" rpy="0 0 0"/>
        <parent link="right_free_up"/>
        <child link="right_l2"/>
    </joint>

    <!--Second coupling-->

    <link name="right_free_down">
        <inertial>
            <origin xyz="0 0 0" rpy="1.5708 0 0"/>
            <mass value="0.05"/>
            <inertia ixx="6.67e-06" ixy="0" ixz="0" iyy="6.67e-06" iyz="0" izz="1e-05"/>
        </inertial>
        <visual>
            <origin xyz="0 0 0" rpy="1.5708 0 0"/>
            <geometry>
                <!--cylinder radius="0.02" length="0.02"/-->
                <mesh filename="package://kamayuc_description/meshes/legs/rover_r_second_coupling.dae"/>
            </geometry>
        </visual>
    </link>

    <gazebo reference="right_free_down">
        <material>Gazebo/Grey</material>
    </gazebo>

    <joint name="right_l2_down_joint" type="revolute">
        <origin xyz="0.156631 0 -0.124365"/>
        <axis xyz="0 1 0"/>
        <limit 
            lower="${-math_pi_over_16}"
            upper="${math_pi_over_16}"
            effort="100.0"
            velocity="100.0" />
        <parent link="right_l2"/>
        <child link="right_free_down"/>
    </joint>

    <gazebo reference="right_l2_down_joint">
        <provideFeedback>true</provideFeedback>
        <implicitSpringDamper>true</implicitSpringDamper>
        <!-- <springStiffness>0.0</springStiffness> -->
        <!-- <springReference>0.0</springReference> -->
    </gazebo>

    <!--Right l4-->
    <link name="right_l4">
        <inertial>
            <origin xyz="0 0 0" rpy="0 0.8456 0"/>
            <mass value="0.1"/>
            <inertia ixx="0.0007572" ixy="0" ixz="0" iyy="0.0007572" iyz="0" izz="1.445e-05"/>
        </inertial>
        <collision>
            <origin xyz="0 0 0" rpy="0 0.8456 0"/>
            <geometry>
                <cylinder radius="0.017" length="0.3"/>
            </geometry>
        </collision>
        <visual>
            <origin xyz="0 0 0" rpy="0 0.8456 0"/>
            <geometry>
                <!--cylinder radius="0.017" length="0.3"/-->
                <mesh filename="package://kamayuc_description/meshes/legs/rover_r_leg4.dae"/>
            </geometry>
        </visual>
    </link>

    <gazebo reference="right_l4">
        <material>Gazebo/Grey</material>
    </gazebo>

    <joint name="right_down_l4_joint" type="fixed">
        <origin xyz="-0.127223 0 -0.112757" rpy="0 0 0"/>
        <parent link="right_free_down"/>
        <child link="right_l4"/>
    </joint>

    <!--Wheel l4-->
    <link name="right_w_l4_link">
        <inertial>
            <origin xyz="0 0 0" rpy="1.5708 0 0"/>
            <mass value="0.2"/>
            <inertia ixx="0.001145" ixy="0" ixz="0" iyy="0.001145" iyz="0" izz="0.00121"/>
        </inertial>
        <collision>
            <origin xyz="0 0 0" rpy="1.5708 0 0"/>
            <geometry>
                <cylinder length="0.18" radius="0.11"/>
            </geometry>
        </collision>
        <visual>
            <origin xyz="0 0 0" rpy="0 0 0"/>
            <geometry>
                <!--cylinder length="0.18" radius="0.11"/-->
                <mesh filename="package://kamayuc_description/meshes/wheels/rover_r_wheel.dae"/>
            </geometry>
        </visual>
    </link>

    <gazebo reference="right_w_l4_link">
        <material>Gazebo/DarkGrey</material>
    </gazebo>

    <joint name="right_w_l4_joint" type="continuous">
        <axis xyz="0 1 0"/>
        <origin xyz="-0.127223 -0.107 -0.112757"/>
        <parent link="right_l4"/>
        <child link="right_w_l4_link"/>
    </joint>


    <transmission name="right_w_l4_transmission">
        <type>transmission_interface/SimpleTransmission</type>
        <actuator name="right_w_l4_actuator">
            <mechanicalReduction>1</mechanicalReduction>
        </actuator>
        <joint name="right_w_l4_joint">
            <hardwareInterface>hardware_interface/VelocityJointInterface</hardwareInterface>
        </joint>
    </transmission>

    <gazebo reference="right_w_l4_joint">
        <provideFeedback>true</provideFeedback>
    </gazebo>


    <!--Right l3-->
    <link name="right_l3">
        <inertial>
            <origin xyz="0 0 0" rpy="0 -0.89972 0"/>
            <mass value="0.1"/>
            <inertia ixx="0.0008605" ixy="0" ixz="0" iyy="0.0008605" iyz="0" izz="1.445e-05"/>
        </inertial>
        <collision>
            <origin xyz="0 0 0" rpy="0 -0.89972 0"/>
            <geometry>
                <cylinder radius="0.017" length="0.32"/>
            </geometry>
        </collision>
        <visual>
            <origin xyz="0 0 0" rpy="0 -0.89972 0"/>
            <geometry>
                <!--cylinder radius="0.017" length="0.32"/-->
                <mesh filename="package://kamayuc_description/meshes/legs/rover_r_leg3.dae"/>
            </geometry>
        </visual>
    </link>

    <gazebo reference="right_l3">
        <material>Gazebo/Grey</material>
    </gazebo>

    <joint name="right_down_l3_joint" type="fixed">
        <origin xyz="0.140968 0 -0.111928" rpy="0 0 0"/>
        <parent link="right_free_down"/>
        <child link="right_l3"/>
    </joint>

    <!--Wheel l3-->
    <link name="right_w_l3_link">
        <inertial>
            <origin xyz="0 0 0" rpy="1.5708 0 0"/>
            <mass value="0.2"/>
            <inertia ixx="0.001145" ixy="0" ixz="0" iyy="0.001145" iyz="0" izz="0.00121"/>
        </inertial>
        <collision>
            <origin xyz="0 0 0" rpy="1.5708 0 0"/>
            <geometry>
                <cylinder length="0.18" radius="0.11"/>
            </geometry>
        </collision>
        <visual>
            <origin xyz="0 0 0" rpy="0 0 0"/>
            <geometry>
                <!--cylinder length="0.18" radius="0.11"/-->
                <mesh filename="package://kamayuc_description/meshes/wheels/rover_r_wheel.dae"/>
            </geometry>
        </visual>
    </link>

    <gazebo reference="right_w_l3_link">
        <material>Gazebo/DarkGrey</material>
    </gazebo>

    <joint name="right_w_l3_joint" type="continuous">
        <axis xyz="0 1 0"/>
        <origin xyz="0.140968 -0.107 -0.111928"/>
        <parent link="right_l3"/>
        <child link="right_w_l3_link"/>
    </joint>

    <transmission name="right_w_l3_transmission">
        <type>transmission_interface/SimpleTransmission</type>
        <actuator name="right_w_l3_actuator">
            <mechanicalReduction>1</mechanicalReduction>
        </actuator>
        <joint name="right_w_l3_joint">
            <hardwareInterface>hardware_interface/VelocityJointInterface</hardwareInterface>
        </joint>
    </transmission>

    <gazebo reference="right_w_l3_joint">
        <provideFeedback>true</provideFeedback>
    </gazebo>


    <!--LEFT-->

    <!--First coupling-->

    <link name="left_free_up">
        <inertial>
            <origin xyz="0 0 0" rpy="1.5708 0 0"/>
            <mass value="0.05"/>
            <inertia ixx="6.67e-06" ixy="0" ixz="0" iyy="6.67e-06" iyz="0" izz="1e-05"/>
        </inertial>
        <visual>
            <origin xyz="0 0 0" rpy="1.5708 0 0"/>
            <geometry>
                <!--cylinder radius="0.02" length="0.02"/-->
                <mesh filename="package://kamayuc_description/meshes/legs/rover_r_first_acople.dae"/>
            </geometry>
        </visual>
    </link>

    <gazebo reference="left_free_up">
        <material>Gazebo/Grey</material>
    </gazebo>

    <joint name="left_up_chasis_joint" type="revolute">
        <origin xyz="0 0.36 0"/>
        <axis xyz="0 1 0"/>
        <limit 
            lower="${-math_pi_over_16}"
            upper="${math_pi_over_16}"
            effort="100.0"
            velocity="100.0" />
        <parent link="chasis"/>
        <child link="left_free_up"/>
    </joint>

    <gazebo reference="left_up_chasis_joint">
        <provideFeedback>true</provideFeedback>
        <implicitSpringDamper>true</implicitSpringDamper>
        <!-- <springStiffness>0.0</springStiffness> -->
        <!-- <springReference>0.0</springReference> -->
    </gazebo>

    <!--left l1-->
    <link name="left_l1">
        <inertial>
            <origin xyz="0 0 0" rpy="0 0.8456 0"/>
            <mass value="0.1"/>
            <inertia ixx="0.003394" ixy="0" ixz="0" iyy="0.003394" iyz="0" izz="1.445e-05"/>
        </inertial>
        <collision>
            <origin xyz="0 0 0" rpy="0 0.8456 0"/>
            <geometry>
                <cylinder radius="0.017" length="0.6375"/>
            </geometry>
        </collision>
        <visual>
            <origin xyz="0 0 0" rpy="0 0.8456 0"/>
            <geometry>
                <!--cylinder radius="0.017" length="0.6375"/-->
                <mesh filename="package://kamayuc_description/meshes/legs/rover_l_leg1.dae"/>
            </geometry>
        </visual>
    </link>

    <gazebo reference="left_l1">
        <material>Gazebo/Grey</material>
    </gazebo>

    <joint name="left_up_l1_joint" type="fixed">
        <origin xyz="-0.253511 0 -0.224685" rpy="0 0 0"/>
        <parent link="left_free_up"/>
        <child link="left_l1"/>
    </joint>

    <!--Wheel l1-->
    <link name="left_w_l1_link">
        <inertial>
            <origin xyz="0 0 0" rpy="1.5708 0 0"/>
            <mass value="0.2"/>
            <inertia ixx="0.001145" ixy="0" ixz="0" iyy="0.001145" iyz="0" izz="0.00121"/>
        </inertial>
        <collision>
            <origin xyz="0 0 0" rpy="1.5708 0 0"/>
            <geometry>
                <cylinder length="0.18" radius="0.11"/>
            </geometry>
        </collision>
        <visual>
            <origin xyz="0 0 0" rpy="0 0 3.1416"/>
            <geometry>
                <!--cylinder length="0.18" radius="0.11"/-->
                <mesh filename="package://kamayuc_description/meshes/wheels/rover_r_wheel.dae"/>
            </geometry>
        </visual>
    </link>

    <gazebo reference="left_w_l1_link">
        <material>Gazebo/DarkGrey</material>
    </gazebo>

    <joint name="left_w_l1_joint" type="continuous">
        <axis xyz="0 1 0"/>
        <origin xyz="-0.253511 0.107 -0.224685"/>
        <parent link="left_l1"/>
        <child link="left_w_l1_link"/>
    </joint>

    <transmission name="left_w_l1_transmission">
        <type>transmission_interface/SimpleTransmission</type>
        <actuator name="left_w_l1_actuator">
            <mechanicalReduction>1</mechanicalReduction>
        </actuator>
        <joint name="left_w_l1_joint">
            <hardwareInterface>hardware_interface/VelocityJointInterface</hardwareInterface>
        </joint>
    </transmission>

    <gazebo reference="left_w_l1_joint">
        <provideFeedback>true</provideFeedback>
    </gazebo>



    <!--left l2-->
    <link name="left_l2">
        <inertial>
            <origin xyz="0 0 0" rpy="0 -0.89972 0"/>
            <mass value="0.1"/>
            <inertia ixx="0.001087225" ixy="0" ixz="0" iyy="0.001087225" iyz="0" izz="1.445e-05"/>
        </inertial>
        <collision>
            <origin xyz="0 0 0" rpy="0 -0.89972 0"/>
            <geometry>
                <cylinder radius="0.017" length="0.36"/>
            </geometry>
        </collision>
        <visual>
            <origin xyz="0 0 0" rpy="0 -0.89972 0"/>
            <geometry>
                <!--cylinder radius="0.017" length="0.36"/-->
                <mesh filename="package://kamayuc_description/meshes/legs/rover_r_leg2.dae"/>
            </geometry>
        </visual>
    </link>

    <gazebo reference="left_l2">
        <material>Gazebo/Grey</material>
    </gazebo>

    <joint name="left_up_l2_joint" type="fixed">
        <origin xyz="0.156631 0 -0.124365" rpy="0 0 0"/>
        <parent link="left_free_up"/>
        <child link="left_l2"/>
    </joint>

    <!--Second coupling-->

    <link name="left_free_down">
        <inertial>
            <origin xyz="0 0 0" rpy="1.5708 0 0"/>
            <mass value="0.05"/>
            <inertia ixx="6.67e-06" ixy="0" ixz="0" iyy="6.67e-06" iyz="0" izz="1e-05"/>
        </inertial>
        <visual>
            <origin xyz="0 0 0" rpy="1.5708 0 0"/>
            <geometry>
                <!--cylinder radius="0.02" length="0.02"/-->
                <mesh filename="package://kamayuc_description/meshes/legs/rover_r_second_coupling.dae"/>
            </geometry>
        </visual>
    </link>

    <gazebo reference="left_free_down">
        <material>Gazebo/Grey</material>
    </gazebo>

    <joint name="left_l2_down_joint" type="revolute">
        <origin xyz="0.156631 0 -0.124365"/>
        <axis xyz="0 1 0"/>
        <limit 
            lower="${-math_pi_over_16}"
            upper="${math_pi_over_16}"
            effort="100.0"
            velocity="100.0" />
        <parent link="left_l2"/>
        <child link="left_free_down"/>
    </joint>

    <gazebo reference="left_l2_down_joint">
        <provideFeedback>true</provideFeedback>
        <implicitSpringDamper>true</implicitSpringDamper>
        <!-- <springStiffness>0.0</springStiffness> -->
        <!-- <springReference>0.0</springReference> -->
    </gazebo>

    <!--left l4-->
    <link name="left_l4">
        <inertial>
            <origin xyz="0 0 0" rpy="0 0.8456 0"/>
            <mass value="0.1"/>
            <inertia ixx="0.0007572" ixy="0" ixz="0" iyy="0.0007572" iyz="0" izz="1.445e-05"/>
        </inertial>
        <collision>
            <origin xyz="0 0 0" rpy="0 0.8456 0"/>
            <geometry>
                <cylinder radius="0.017" length="0.3"/>
            </geometry>
        </collision>
        <visual>
            <origin xyz="0 0 0" rpy="0 0.8456 0"/>
            <geometry>
                <!--cylinder radius="0.017" length="0.3"/-->
                <mesh filename="package://kamayuc_description/meshes/legs/rover_l_leg4.dae"/>
            </geometry>
        </visual>
    </link>

    <gazebo reference="left_l4">
        <material>Gazebo/Grey</material>
    </gazebo>

    <joint name="left_down_l4_joint" type="fixed">
        <origin xyz="-0.127223 0 -0.112757" rpy="0 0 0"/>
        <parent link="left_free_down"/>
        <child link="left_l4"/>
    </joint>

    <!--Wheel l4-->
    <link name="left_w_l4_link">
        <inertial>
            <origin xyz="0 0 0" rpy="1.5708 0 0"/>
            <mass value="0.2"/>
            <inertia ixx="0.001145" ixy="0" ixz="0" iyy="0.001145" iyz="0" izz="0.00121"/>
        </inertial>
        <collision>
            <origin xyz="0 0 0" rpy="1.5708 0 0"/>
            <geometry>
                <cylinder length="0.18" radius="0.11"/>
            </geometry>
        </collision>
        <visual>
            <origin xyz="0 0 0" rpy="0 0 3.1416"/>
            <geometry>
                <!--cylinder length="0.18" radius="0.11"/-->
                <mesh filename="package://kamayuc_description/meshes/wheels/rover_r_wheel.dae"/>
            </geometry>
        </visual>
    </link>

    <gazebo reference="left_w_l4_link">
        <material>Gazebo/DarkGrey</material>
    </gazebo>

    <joint name="left_w_l4_joint" type="continuous">
        <axis xyz="0 1 0"/>
        <origin xyz="-0.127223 0.107 -0.112757"/>
        <parent link="left_l4"/>
        <child link="left_w_l4_link"/>
    </joint>

    <transmission name="left_w_l4_transmission">
        <type>transmission_interface/SimpleTransmission</type>
        <actuator name="left_w_l4_actuator">
            <mechanicalReduction>1</mechanicalReduction>
        </actuator>
        <joint name="left_w_l4_joint">
            <hardwareInterface>hardware_interface/VelocityJointInterface</hardwareInterface>
        </joint>
    </transmission>

    <gazebo reference="left_w_l4_joint">
        <provideFeedback>true</provideFeedback>
    </gazebo>

    <!--left l3-->
    <link name="left_l3">
        <inertial>
            <origin xyz="0 0 0" rpy="0 -0.89972 0"/>
            <mass value="0.1"/>
            <inertia ixx="0.0008605" ixy="0" ixz="0" iyy="0.0008605" iyz="0" izz="1.445e-05"/>
        </inertial>
        <collision>
            <origin xyz="0 0 0" rpy="0 -0.89972 0"/>
            <geometry>
                <cylinder radius="0.017" length="0.32"/>
            </geometry>
        </collision>
        <visual>
            <origin xyz="0 0 0" rpy="0 -0.89972 0"/>
            <geometry>
                <!--cylinder radius="0.017" length="0.32"/-->
                <mesh filename="package://kamayuc_description/meshes/legs/rover_l_leg3.dae"/>
            </geometry>
        </visual>
    </link>

    <gazebo reference="left_l3">
        <material>Gazebo/Grey</material>
    </gazebo>

    <joint name="left_down_l3_joint" type="fixed">
        <origin xyz="0.140968 0 -0.111928" rpy="0 0 0"/>
        <parent link="left_free_down"/>
        <child link="left_l3"/>
    </joint>

    <!--Wheel l3-->
    <link name="left_w_l3_link">
        <inertial>
            <origin xyz="0 0 0" rpy="1.5708 0 0"/>
            <mass value="0.2"/>
            <inertia ixx="0.001145" ixy="0" ixz="0" iyy="0.001145" iyz="0" izz="0.00121"/>
        </inertial>
        <collision>
            <origin xyz="0 0 0" rpy="1.5708 0 0"/>
            <geometry>
                <cylinder length="0.18" radius="0.11"/>
            </geometry>
        </collision>
        <visual>
            <origin xyz="0 0 0" rpy="0 0 3.1416"/>
            <geometry>
                <!--cylinder length="0.18" radius="0.11"/-->
                <mesh filename="package://kamayuc_description/meshes/wheels/rover_r_wheel.dae"/>
            </geometry>
        </visual>
    </link>

    <gazebo reference="left_w_l3_link">
        <material>Gazebo/DarkGrey</material>
    </gazebo>

    <joint name="left_w_l3_joint" type="continuous">
        <axis xyz="0 1 0"/>
        <origin xyz="0.140968 0.107 -0.111928"/>
        <parent link="left_l3"/>
        <child link="left_w_l3_link"/>
    </joint>

    <transmission name="left_w_l3_transmission">
        <type>transmission_interface/SimpleTransmission</type>
        <actuator name="left_w_l3_actuator">
            <mechanicalReduction>1</mechanicalReduction>
        </actuator>
        <joint name="left_w_l3_joint">
            <hardwareInterface>hardware_interface/VelocityJointInterface</hardwareInterface>
        </joint>
    </transmission>
    
    <gazebo reference="left_w_l3_joint">
        <provideFeedback>true</provideFeedback>
    </gazebo>

</robot>